Workbook

Sheet BancoBPM_BalanceSheet
A1: Banco BPM: Reclassified consolidated balance sheet
A2: Figures in thousands of euro | B2: 31/12/2023 | C2: Duration | D2: Yield | F2: Duration asset | G2: Product | I2: Asset change | J2: -0.0025
A3: Cash and cash equivalents | B3: 18297496 | I3: =A4 -> Loans at AC | J3: =-C4*B4*(J2/(1+D4)) -> 3412614.1
A4: Loans at AC | B4: 109568359 | C4: 13.1 | D4: 0.0515 | G4: =B4*C4 -> 1.4353455e+09 | I4: =A7 -> Other financial assets and hedging derivatives | J4: =-C7*B7*(J2/(1+D7)) -> 184126.54
A5: - Loans to banks | B5: 4141630 | I5: =A11 -> Financial assets pertaining to insurance companies | J5: =-C11*B11*(J2/(1+D11)) -> 403237.19
A6: - Loans to customers | B6: 105426729 | I6: =A12 -> Interests in associates and joint ventures | J6: =-C12*B12*(J2/(1+D12)) -> 4696.7372
A7: Other financial assets and hedging derivatives | B7: 43706381 | C7: 1.75 | D7: 0.0385 | G7: =B7*C7 -> 76486167
A8: - At FV through Profit and Loss | B8: 7391989
A9: - At FV through OCI | B9: 10692718
A10: - At AC | B10: 25621674 | I10: Total | J10: =SUM(J3:J7) -> 4004674.6
A11: Financial assets pertaining to insurance companies | B11: 15345008 | C11: 11 | D11: 0.0465 | G11: =B11*C11 -> 168795088
A12: Interests in associates and joint ventures | B12: 1454249 | C12: 1.35 | D12: 0.045 | G12: =B12*C12 -> 1963236.2
A13: Property, plant and equipment | B13: 2857953 | F13: Sum | G13: =SUM(G4:G12) -> 1.68259e+09
A14: Intangible assets | B14: 1257425 | F14: Weighted avg duration | G14: =G13/B18 -> 8.324215
A15: Tax assets | B15: 4201154
A16: Non-current assets and disposal groups held for sale | B16: 468685 | I16: Liabilities change | J16: -0.0015
A17: Other asset items | B17: 4975263 | I17: =A19 -> Direct bank funding | J17: =-C19*B19*(J16/(1+D19)) -> 243463.79
A18: Total assets | B18: 202131973 | F18: DURATION LIABILITIES | G18: Product | I18: =A23 -> - Financial liabilities pertaining to insurance companies measured at fair value | J18: =-C23*B23*(J16/(1+D23)) -> 23839.414
A19: Direct bank funding | B19: 120770064 | C19: 1.35 | D19: 0.0045 | G19: =C19*B19 -> 1.6303959e+08 | I19: =A24 -> - Insurance liabilities | J19: =-C24*B24*(J16/(1+D24)) -> 91709.965
A20: - Due to customers | B20: 101861964 | I20: =A27 -> Other financial liabilities designated at fair value | J20: =-C27*B27*(J16/(1+D27)) -> 78704.314
A21: - Securities and financial liabilities designated at FV | B21: 18908100 | I21: =A28 -> Other financial liabilities pertaining to insurance companies | J21: =-C28*B28*(J16/(1+D28)) -> 127.36207
A22: Direct funding from insurance business and insurance liabilities | B22: 15039762 | I22: =A32 -> Other liability items | J22: =-C32*B32*(J16/(1+D32)) -> 2833.2901
A23: - Financial liabilities pertaining to insurance companies measured at fair value | B23: 2800121 | C23: 5.9 | D23: 0.0395 | G23: =C23*B23 -> 16520714
A24: - Insurance liabilities | B24: 12239641 | C24: 5.25 | D24: 0.051 | G24: =C24*B24 -> 64258115
A25: Due to banks | B25: 21690773 | I25: Total | J25: =SUM(J17:J22) -> 440678.14
A26: Lease payables | B26: 670773
A27: Other financial liabilities designated at fair value | B27: 25697583 | C27: 2.1 | D27: 0.0285 | G27: =C27*B27 -> 53964924
A28: Other financial liabilities pertaining to insurance companies | B28: 72561 | C28: 1.2 | D28: 0.0255 | G28: =C28*B28 -> 87073.2 | I28: ∆E=∆A-∆L | J28: =J10-J25 -> 3563996.5
A29: Liability provisions | B29: 894841
A30: Tax liabilities | B30: 453929
A31: Liabilities associated with assets classified as held for sale | B31: 212011 | I31: Change in equity% | J31: =((B33+B34+J28)-(B33+B34))/(B33+B34) -> 0.25387917
A32: Other liability items | B32: 2591516 | C32: 0.75 | D32: 0.029 | G32: =C32*B32 -> 1943637
A33: Non-controlling interests | B33: 68 | F33: Sum | G33: =SUM(G19:G32) -> 2.9981405e+08
A34: Group shareholders' equity | B34: 14038092 | F34: Weighted avg duration | G34: =G33/B50 -> 1.5939602
A35: Total liabilities and shareholders' equity | B35: 202131973
A38: Reserve requested by ECB | B38: =B39*0.025 -> 1509625.8
A39: Deposits | B39: =B19*0.5 -> 60385032
A40: Reserves | B40: =B3 -> 18297496
A41: Interest - earning assets | B41: =B11+B7+B4 -> 168619748
A42: ROA = net income / total asets | B42: =BancoBPM_IncomeStatement!B32/BancoBPM_BalanceSheet!B18 -> 0.0062555813
...

Sheet BancoBPM_IncomeStatement
A1: Banco BPM: Reclassified consolidated income statement
A2: Figures in thousands of euro | B2: 2023
A3: Net interest income | B3: 3289228
A4: Gains (losses) on interests in associates and joint ventures carried at equity | B4: 144097
A5: Financial margin | B5: 3433325
A6: - Net fee and commission income | B6: 1860019
A7: - Other net operating income | B7: 81276
A8: - Net financial result | B8: -79029
A9: - Profit (loss) on insurance business | B9: 45851
A10: Other operating income | B10: 1908117
A11: Operating income | B11: 5341442
A12: - Personnel expenses | B12: -1671952
A13: - Other administrative expenses | B13: -652393
A14: - Net value adjustments to property, plant and equipment and intangible assets | B14: -246818
... A27: - Bancassurance impacts net of taxes | B27: -22245
A28: - Goodwill impairment
A29: - Change in own credit risk on Certificates issued by the Group, net of taxes | B29: -3463
A30: - Purchase Price Allocation net of taxes | B30: -28340
A31: Profit (loss) for the year attributable to non-controlling interests | B31: 22
A32: Parent Company's profit (loss) for the year | B32: 1264453

Sheet UniCredit_BalanceSheet
A1: UniCredit: Reclassified consolidated balance sheet
A2: Figures in million | B2: 31.12.2023 | C2: Duration | D2: Yield
A3: Cash and cash balances | B3: 61000 | F3: Duration asset | G3: Product | I3: Asset change | J3: -0.0025
A4: Financial assets held for trading | B4: 57274 | C4: 1.2 | D4: 0.0365 | G4: =B4*C4 -> 68728.8 | I4: =A4 -> Financial assets held for trading | J4: =-C4*B4*(J3/(1+D4)) -> 165.77135
A5: Loans to banks | B5: 39434 | C5: 0.2 | D5: 0.004 | G5: =B5*C5 -> 7886.8 | I5: =A5 -> Loans to banks | J5: =-C5*B5*(J3/(1+D5)) -> 19.638446
A6: Loans to customers | B6: 429452 | C6: 14.55 | D6: 0.0635 | G6: =B6*C6 -> 6248526.6 | I6: =A6 -> Loans to customers | J6: =-C6*B6*(J3/(1+D6)) -> 14688.591
A7: Other financial assets | B7: 162953 | C7: 0.02 | D7: 0.003 | G7: =B7*C7 -> 3259.06 | I7: =A7 -> Other financial assets | J7: =-C7*B7*(J3/(1+D7)) -> 8.1232802
A8: Hedging instruments | B8: -1340 | I8: =A14 -> Other assets | J8: =-C14*B14*(J3/(1+D14)) -> 9.7511155
A9: Property, plant and equipment | B9: 8628
A10: Goodwill
A11: Other intangible assets | B11: 2272 | I11: Total | J11: =SUM(J4:J8) -> 14891.875
A12: Tax assets | B12: 11818 | G12: =B14*C14 -> 3933.6
A13: Non-current assets and disposal groups classified as held for sale | B13: 370
A14: Other assets | B14: 13112 | C14: 0.3 | D14: 0.0085 | F14: Sum | G14: =SUM(G4:G12) -> 6332334.9
A15: Total assets | B15: 784973 | F15: Weighted avg duration | G15: =G14/B15 -> 8.0669461
A16: Deposits from banks | B16: 71042 | C16: 0.25 | D16: 0.004 | F16: Duration liabilities | G16: Product
A17: Deposits from customers | B17: 495716 | C17: 1.1 | D17: 0.0035 | G17: =B16*C16 -> 17760.5 | I17: Liabilities change | J17: -0.0015
A18: Debt securities issued | B18: 89845 | C18: 0.04 | D18: 0.0015 | G18: =B17*C17 -> 545287.6 | I18: =A16 -> Deposits from banks | J18: =-C16*B16*(J17/(1+D16)) -> 26.534612
A19: Financial liabilities held for trading | B19: 38022 | C19: 1.65 | D19: 0.025 | G19: =B18*C18 -> 3593.8 | I19: =A17 -> Deposits from customers | J19: =-C17*B17*(J17/(1+D17)) -> 815.07862
A20: Other financial liabilities | B20: 13751 | C20: 1.5 | D20: 0.0325 | G20: =B19*C19 -> 62736.3 | I20: =A18 -> Debt securities issued | J20: =-C18*B18*(J17/(1+D18)) -> 5.3826261
A21: Hedging instruments | B21: -10573 | G21: =B20*C20 -> 20626.5 | I21: =A19 -> Financial liabilities held for trading | J21: =-C19*B19*(J17/(1+D19)) -> 91.80922
A22: Tax liabilities | B22: 1483 | I22: =A20 -> Other financial liabilities | J22: =-C20*B20*(J17/(1+D20)) -> 29.96586
A23: Liabilities included in disposal groups classified as held for sale | I23: =A24 -> Other liabilities | J23: =-C24*B24*(J17/(1+D24)) -> 199.19884
A24: Other liabilities | B24: 21445 | C24: 6.4 | D24: 0.0335 | G24: =B24*C24 -> 137248
A25: Minorities | B25: 164
A26: Capital and reserves | B26: 54572 | I26: Total | J26: =SUM(J18:J25) -> 1167.9698
A27: Group stated net profit (loss) | B27: 9506 | F27: Sum | G27: =SUM(G17:G24) -> 787252.7
A28: Total liabilities and shareholders' equity | B28: 784973 | F28: Weighted avg duration | G28: =G27/B39 -> 1.0922975
I29: ∆E=∆A-∆L | J29: =J11-J26 -> 13723.905
I31: Change in equity% | J31: =((B25+B27+B26+J29)-(B25+B26+B27))/(B25+B26+B27) -> 0.21362824
A32: Interest earnings assets | B32: =B4+B5+B6+B7 -> 689113
A33: ROA | B33: =UniCredit_IncomeStatement!B29/UniCredit_BalanceSheet!B15 -> 0.012111245 | C33: =B33 -> 0.012111245
A34: ROE | B34: =UniCredit_IncomeStatement!B29/(UniCredit_BalanceSheet!B26 +B27) -> 0.14836605 | C34: =B34 -> 0.14836605
A35: Worthless loans | B35: =B6*0.06 -> 25767.12
A36: New net capital | B36: =B26-B35 -> 28804.88
A37: Reduction of net capital | B37: =B35/B26 -> 0.47216741
A38: Equity multiplier = total asstes/ total equity | B38: =B15/B26 -> 14.384171
A39: Total liabilities | B39: =SUM(B16:B24) -> 720731
A40: Leverage Ratio | B40: =B39/B15 -> 0.91816024
A41: Leverage-adjusted duration gap | B41: =G15-G28*B40 -> 7.0640419
...

Sheet UniCredit_IncomeStatement
A1: UniCredit: Reclassified consolidated income statement
A2: Figures in million | B2: 2023
A3: Net interest | B3: 14005
A4: Dividends | B4: 459
A5: Fees | B5: 7463
A6: Trading income | B6: 1845
A7: Other expenses/income | B7: 72
A8: Revenue | B8: =SUM(B3:B7) -> 23844
A9: HR costs | B9: -5860
A10: Non HR costs | B10: -3075
A11: Recovery of expenses | B11: 542
A12: Amortisations and depreciations | B12: -1078
A13: Operating costs | B13: -9471
A14: GROSS OPERATING PROFIT (LOSS) | B14: 14373
A15: Loan Loss Provisions (LLPs) | B15: -548
A16: NET OPERATING PROFIT (LOSS) | B16: 13825
A17: Other charges and provisions | B17: -1041
A18: - of which: systemic charges | B18: -955
A19: Integration costs | B19: -1060
A20: Net income from investments | B20: -272
... A22: Income taxes | B22: -1914
A23: Profit (Loss) of discontinued operations
A24: NET PROFIT (LOSS) FOR THE PERIOD | B24: 9538
A25: Minorities | B25: -27
A26: NET PROFIT (LOSS) ATTRIBUTABLE TO THE GROUP BEFORE PPA | B26: 9511
A27: Purchase Price Allocation (PPA) | B27: -4
A28: Goodwill impairment
A29: GROUP STATED NET PROFIT (LOSS) | B29: 9507

Sheet Solutions
A1: Questions | B1: BPM | C1: UniCredit | D1: Notes
A2: Part I: Bank Balance Sheet
A3: Question 1
A4: Net Worth | B4: =BancoBPM_BalanceSheet!B33+BancoBPM_BalanceSheet!B34 -> 14038160 | C4: =UniCredit_BalanceSheet!B25+UniCredit_BalanceSheet!B26+UniCredit_BalanceSheet!B27 -> 64242
A5: Question 2
A6: Deposits from costumers | B6: =BancoBPM_BalanceSheet!B20*50% -> 50930982 | D6: Since Banco BPM has cash and cash equialents that exceed the required reserve, the bank is compliant with the ECB's reserve requirement ratio. If Banco BPM was not compliant, there are different strategies that the bank could have adopted like borrowing from other banks or issue Certificated of Deposits (CDs), borrowing from the ECB, selling securities and deposit proceeds with ECB or selling some loans.
A7: Cash and cash equivalents | B7: =BancoBPM_BalanceSheet!B3 -> 18297496
A8: Required reserve (2.5%) | B8: =2.5%*B6 -> 1273274.6
A9: Question 3
A10: ROE | B10: =B11*B24 -> 0.090072559 | C10: =C11*C24 -> 0.1479873 | D10: UniCredit is more profitable than Banco BPM based on ROE and ROA.
A11: ROA | B11: =BancoBPM_IncomeStatement!B32/BancoBPM_BalanceSheet!B18 -> 0.0062555813 | C11: =UniCredit_IncomeStatement!B29/UniCredit_BalanceSheet!B15 -> 0.012111245
A12: Question 4
A13: Asset Utilization | B13: =BancoBPM_IncomeStatement!B11/BancoBPM_BalanceSheet!B18 -> 0.026425518 | C13: =UniCredit_IncomeStatement!B8/UniCredit_BalanceSheet!B15 -> 0.030375567 | D13: UniCredit is more efficient than Banco BPM, with better expense control due to lower costs and provisions and stronger income generation (higher asset utilization, profit margin) making it more profitable compared to Banco BPM.
A14: Profit Margin | B14: =BancoBPM_IncomeStatement!B32/BancoBPM_IncomeStatement!B11 -> 0.23672503 | C14: =UniCredit_IncomeStatement!B29/UniCredit_IncomeStatement!B8 -> 0.39871666
A15: Interest Expense Ratio | B15: N/A | C15: N/A
A16: Provision for Loss Ratio | B16: =-BancoBPM_IncomeStatement!B17/BancoBPM_IncomeStatement!B11 -> 0.10457738 | C16: =-UniCredit_IncomeStatement!B15/UniCredit_IncomeStatement!B8 -> 0.022982721
A17: Noninterest Expense Ratio | B17: =-(BancoBPM_IncomeStatement!B12+BancoBPM_IncomeStatement!B13+BancoBPM_IncomeStatement!B14)/BancoBPM_IncomeStatement!B11 -> 0.48136121 | C17: =-(UniCredit_IncomeStatement!B9+UniCredit_IncomeStatement!B10+UniCredit_IncomeStatement!B11+UniCredit_IncomeStatement!B12)/UniCredit_IncomeStatement!B8 -> 0.39720684
A18: Tax Ratio | B18: =-BancoBPM_IncomeStatement!B23/BancoBPM_IncomeStatement!B11 -> 0.11321868 | C18: =-UniCredit_IncomeStatement!B22/UniCredit_IncomeStatement!B8 -> 0.080271766
A19: NIM | B19: =BancoBPM_IncomeStatement!B3/(BancoBPM_BalanceSheet!B4+BancoBPM_BalanceSheet!B7+BancoBPM_BalanceSheet!B11+BancoBPM_BalanceSheet!B12) -> 0.019339982 | C19: =UniCredit_IncomeStatement!B3/(UniCredit_BalanceSheet!B4+UniCredit_BalanceSheet!B5+UniCredit_BalanceSheet!B6+UniCredit_BalanceSheet!B7+UniCredit_BalanceSheet!B8) -> 0.020362823
A20: Question 5
A21: Loss on Loans | B21: =8%*(BancoBPM_BalanceSheet!B4) -> 8765468.7 | C21: =6%*(UniCredit_BalanceSheet!B5+UniCredit_BalanceSheet!B6) -> 28133.16 | D21: After the distress, both banks experiences a decline in their net worth. In particular, Banco BPM was affected mor due to the higher loan's rate of default.
A22: New Net Worth | B22: =B4-B21 -> 5272691.3 | C22: =C4-C21 -> 36108.84
A23: Question 6
A24: Equity Multiplier of both banks | B24: =BancoBPM_BalanceSheet!B18/Solutions!B4 -> 14.398751 | C24: =UniCredit_BalanceSheet!B15/Solutions!C4 -> 12.219 | D24: To raise the equity multiplier and therfore increase ROE, the bank can either reduce capital (e.g., share buybacks or dividends) or increase assets (e.g., issuing debt).
A25: Total assests after the merge (millions) | B25: =UniCredit_BalanceSheet!B15+BancoBPM_BalanceSheet!B18/1000 -> 987104.97
A26: Net Worth after the merge (millions) | B26: =B4/1000+C4 -> 78280.16
A27: Equity Multiplier after the merge | B27: =B25/B26 -> 12.6099
A28: Question 7
A29: The proposed merger between UniCredit and Banco BPM aligns with the strategic rationale outlined in the report, aiming to consolidate market positioning and amplify competitive strength. Post-merger, UniCredit would surpass Intesa Sanpaolo to become the largest Italian bank by market capitalization, significantly reshaping the national banking landscape. This consolidation would create a duopoly between Intesa and UniCredit, both holding substantial market leverage compared to smaller domestic players. Such a structural shift is likely to draw regulatory scrutiny over concerns of reduced competition and increased systemic risk, emphasizing the need to balance financial ambitions with antitrust and market stability considerations.
A30: Research on banks by market capitalization: Intesa Sanpaolo: €69.16 billion UniCredit: €61.12 billion Mediobanca: €12.77 billion FinecoBank: €9.22 billion Banco BPM: €9.18 billion
A34: Part II: Interest Rate Risk | B34: BPM | C34: UniCredit | D34: Notes
A35: 1) Leverage-adjusted duration gap (in years) | B35: =BancoBPM_BalanceSheet!$B$52 -> 6.8409561 | C35: =UniCredit_BalanceSheet!$B$41 -> 7.0640419 | D35: DA-DL * Laverage Ratio
A36: 2) Change in the value of assets | B36: 4004674.6 | C36: 14891.88 | D36: ∆A=-D*A*∆R/(1 + R)
A37: Change in the value of liabilities | B37: 440678.14 | C37: 1167.97 | D37: ∆A=-D*L*∆R/(1 + R)
A38: Change in equity | B38: 3563996.5 | C38: 13723.91 | D38: Since the duration of the assets is longer, the decrease in interest rate caused a positive equity change. As expected BPM bank is more sensitive to changes in interest rates since the duration mismatch between assets and liabilities is greater, consequently BPM's equity value has undergone a greater variation than Unicredit's
A39: 3) Change in equity | B39: -13827759 | C39: -55450.82 | D39: ∆A=-D*A*∆R/(1 + R) , Since the duration of assets is longer than that of liabilities, the increase in interest rate has led to a decrese in equity. The decrease in equity of BPM is higher since it is more sensitive.
A40: New equity | B40: 210400.56 | C40: 8791.18
A41: Change in equity | B41: 6913879.7 | C41: 27725.41 | D41: ∆E = −DGAP × A × ∆R/(1 + R) , Since the duration of assets is longer than that of liabilities, the decrease in interest rate has led to an increase in equity. The increse in equity of BPM is higher since it is more sensitive.
A42: New equity | B42: 20952040 | C42: 91967.41
A46: Part III: Liquidity Risk
...
